Workbook

Sheet Nizar
A1: 1 | B1: نَصَر | C1: verb:assist;render victorious;deliver
A2: 2 | B2: تَضْمِين | C2: noun:inclusion;modulation;implication
A3: 3 | B3: هَوَّم | C3: verb:doze off;fall asleep;exaggerate
A4: 4 | B4: مُونَة | C4: noun:provisions;mortar
A5: 5 | B5: حِمَى | C5: noun:protection
A6: 6 | B6: غَنَم | C6: noun:sheep;goat;goats;sheep;goats
A7: 7 | B7: مِران | C7: noun:practice;experience;skill
A8: 8 | B8: مُتَطَيِّر | C8: adj:pessimist;superstitious
A9: 9 | B9: تَبَرَّج | C9: verb:adorn;embellish
A10: 10 | B10: أَشْدَق | C10: adj:loud-mouthed
A11: 11 | B11: تَرْنِيخ | C11: noun:stagnation
A12: 12 | B12: مُبَيِّن | C12: adj:indicating|noun:indicator
... A100: 100 | B100: نُشُوئِيّ | C100: adj:evolutionist
A101: x | B101: ساقَة | C101: noun:rear guard
A102: x | B102: أَغْيَن | C102: adj:bushy;dense
A103: x | B103: قَيْل | C103: noun:chief;chieftain;chiefs;chieftains
A104: x | B104: جُزازَة | C104: noun:tag;label
A105: x | B105: دِيماس | C105: noun:dungeon;catacomb;dungeons;catacombs
A106: x | B106: مُوَرِّق | C106: noun:stationer
A107: x | B107: قَذَّف | C107: verb:oar
A108: x | B108: دَعَر | C108: noun:immorality;indecency
A109: x | B109: مُقِيمِيَّة | C109: noun:residency
A110: x | B110: مَغَر | C110: noun:reddish
A111: x | B111: جَعِيدِيّ | C111: adj:loafer;bum
A112: x | B112: سَمانَة | C112: noun:calf
B113: دَجَّل | C113: verb:coat;deceive
B114: كَلْسِيط | C114: noun:stockings
B115: مَعْصُوم | C115: adj:impeccable;inviolable
B116: ضُحَى | C116: noun:forenoon;overnight;suddenly
B117: وَبِيل | C117: noun:unhealthy;evil
B118: اِسْتَلْزَم | C118: verb:be deemed necessary;be required;deem necessary;require
B119: عُجَرِيّ | C119: adj:nodular
B120: صاعِدَة | C120: noun:stalagmite;stalagmites
B121: مُشْرِق | C121: adj:splendid;shining;bright;auspicious (future)
B122: مُسْتَطِير | C122: adj:imminent;scattered
B123: اِسْتَساغ | C123: verb:find pleasant;admit
B124: اِجْتَذَب | C124: verb:attract;allure
... B200: فَسِيح | C200: adj:wide;ample;roomy

Sheet Sara
A1: 1 | B1: ضُلُوع | C1: noun:involvement;complicity
A2: 2 | B2: تَحَفَّى | C2: verb:be affectionate
A3: 3 | B3: تَكْتَكَة | C3: noun:ticking
A4: 4 | B4: عَذْب | C4: adj:sweet;pleasant
A5: 5 | B5: أَنِيمِيّ | C5: adj:anemic
A6: 6 | B6: رَهْو | C6: noun:calm;quiet;tranquillity;crane;cranes
A7: 7 | B7: مُصاب | C7: adj:afflicted;injured;wounded|noun:afflicted;injured;wounded
A8: 8 | B8: حاضِرَة | C8: noun:capital cities;metropolis
A9: 9 | B9: وَحْف | C9: noun:luxuriant;black
A10: 10 | B10: أَخْصَب | C10: verb:be fertile|adj_comp:more/most fertile;more/most productive
A11: 11 | B11: تَفَخَّر | C11: verb:be proud
A12: 12 | B12: شَهْر | C12: noun:month;months
... A100: 100 | B100: اِنْحَدَر | C100: verb:descend;decline;come (from)
B101: اِئْتِمانِيّ | C101: adj:fiduciary;credit
B102: سِيان | C102: noun:cyanogen
B103: مَحُل | C103: verb:be barren;plot against;intrigue against
B104: مِدَكّ | C104: noun:ramrod;tamper rammer
B105: صَوْصَى | C105: verb:squeak;cheep
B106: لاوِنْجِيَّة | C106: noun:housemaid
B107: لَذاذَة | C107: noun:delight;delectation;delights;pleasures
B108: أَفّاق | C108: noun:vagabond;globe-trotter
B109: اِسْتَهْيَم | C109: verb:infatuate;captivate
B110: سِبِيداج | C110: noun:white lead;ceruse
B111: تَذْكَرِيّ | C111: adj:ticket clerk
B112: إِعْوال | C112: noun:wailing;lamentation
... B200: ضِغْن | C200: noun:hatred;malice

Sheet Nasser
A1: 1 | B1: جارِحَة | C1: noun:extremities;predatory
A2: 2 | B2: سَوِيّ | C2: adj:straight;correct;together;jointly;in common
A3: 3 | B3: أُوام | C3: noun:thirst
A4: 4 | B4: جِوار | C4: noun:near;proximity;next to
A5: 5 | B5: رَتابَة | C5: noun:monotony
A6: 6 | B6: قَطْرانِيّ | C6: adj:tar-like
A7: 7 | B7: مُشْتَمَل | C7: noun:contents
A8: 8 | B8: كَدَم | C8: verb:bite;bruise
A9: 9 | B9: فُنْدُقِيّ | C9: adj:hotel;hotel-management
A10: 10 | B10: دَرَكِيّ | C10: adj:policeman
A11: 11 | B11: مِنَوِيّ | C11: adj:seminal;semen
A12: 12 | B12: نَفْسِيّ | C12: adj:mental;spiritual;psychological
... A100: 100 | B100: بادَر | C100: verb:initiate;surprise
A101: x | B101: يُسْر | C101: noun:ease;facility;affluence
A102: x | B102: جَلْفَن | C102: verb:galvanize
A103: x | B103: كَرارِطِيّ | C103: adj:carrier;drayman
A104: x | B104: أَنْجلُوسَكْسُون | C104: adj:Anglo-Saxons|noun:Anglo-Saxons
A105: x | B105: عاذ | C105: verb:take refuge;seek protection
A106: x | B106: شَعْفَة | C106: noun:summit;summits
A107: x | B107: سَحَّر | C107: verb:enchant;fascinate
A108: x | B108: مُنَضِّد | C108: noun:typesetter;compositor
A109: x | B109: باحَت | C109: verb:promise
A110: x | B110: جُذْمُور | C110: noun:stump;stumps
A111: x | B111: قُشّاش | C111: noun:gleanings
A112: x | B112: اِعْتِياص | C112: noun:difficulty;intractability
... A137: x | B137: بانْطَلُون | C137: noun:trousers
B138: مَحَّى | C138: verb:be wipped out;be eradicated;be exterminated;wipe out;eradicate;exterminate
B139: أَشْرَق | C139: verb:be risen;be shone;rise;shine
B140: اِنْتِصاب | C140: noun:setting up;erecting
B141: اِدِّغام | C141: noun:incorporation;coalescence
B142: تَمالَك | C142: verb:control
B143: طَمِث | C143: verb:menstruate
B144: قالَة | C144: noun:speech;talk
B145: تَدْلِيل | C145: noun:proof;evidence;substantiation
B146: بُنْط | C146: noun:point;points
B147: حَرِيف | C147: noun:customer;customers
B148: مُسَفْلَت | C148: adj:asphalted;paved
B149: حَذا | C149: verb:be imitated;imitate
... B200: خَبَأ | C200: verb:hide;conceal

Sheet Salam
A1: 1 | B1: مَجَرِّيّ | C1: adj:galactic
A2: 2 | B2: آمِر | C2: noun:commander;commandant
A3: 3 | B3: اِسْتَوْصَى | C3: verb:adopt;assume;be adopted;be assumed
A4: 4 | B4: اِنْتِفاء | C4: noun:absence;lack
A5: 5 | B5: نَبَّس | C5: verb:utter;speak
A6: 6 | B6: تَعَسَّر | C6: verb:be difficult
A7: 7 | B7: مَطْمُور | C7: adj:underground
A8: 8 | B8: مُصَوِّبَة | C8: noun:sight;viewfinder
A9: 9 | B9: فَأْفَأ | C9: verb:stammer;stutter
A10: 10 | B10: دِفاع | C10: noun:defense;in defense (of)
A11: 11 | B11: اِسْتَدْفَع | C11: verb:try to ward off
A12: 12 | B12: اِشْتَمَل | C12: verb:include;contain;comprise
... A100: 100 | B100: اِعْتِقادِيَّة | C100: noun:dogmatism
A101: x | B101: خَلُع | C101: verb:be dissolute
A102: x | B102: ذُعاف | C102: noun:lethal
A103: x | B103: مُسْكَة | C103: noun:handle;grip
A104: x | B104: ضَوْع | C104: noun:fragrance
A105: x | B105: قَبّ | C105: verb:bristle;rise;swell|noun:hub;lever;beam;hubs;levers;beams
A106: x | B106: تَهْلِين | C106: noun:Hellenization
A107: x | B107: قُمْرُقِيّ | C107: adj:customs;import tariff
A108: x | B108: نَجَز | C108: verb:accomplish;carry out
A109: x | B109: لِفِيثان | C109: noun:leviathan
A110: x | B110: فرامْبُواز | C110: noun:raspberry
A111: x | B111: زُبّ | C111: noun:penis;penises
A112: x | B112: جَوِي | C112: verb:be stricken;be overcome
... A116: x | B116: أَسالَة | C116: noun:elliptic;oval
B117: جَلْفانُومِتر | C117: noun:galvanometer
B118: اِسْتَوْجَب | C118: verb:require;make necessary
B119: حَصِين | C119: adj:inaccessible;fortified;immune
B120: لاغَز | C120: verb:equivocate;speak in riddles
B121: رَمْس | C121: noun:grave;tomb;graves;tombs
B122: داهِم | C122: adj:looming;threatening;menacing
B123: اِزْدَرَد | C123: verb:swallow
B124: عازِب | C124: adj:unmarried
B125: صائِغ | C125: noun:jeweler;jewelers
B126: نَفْعِيّ | C126: adj:utilitarian;profit-oriented
B127: صُراخِيّ | C127: adj:shouting;screaming
B128: مَقْبُوض | C128: adj:arrested;seized;clenched
... B200: قَتامَة | C200: noun:darkness;gloom

Sheet Dima
A1: 1 | B1: تَعِب | C1: verb:be tired;work hard
A2: 2 | B2: مِرْساة | C2: noun:anchorage
A3: 3 | B3: تَخاذَل | C3: verb:decrease
A4: 4 | B4: أَهْلَك | C4: verb:be destroyed;destroy
A5: 5 | B5: اِحْتَسَى | C5: verb:be drunk;be sipped;drink;sip
A6: 6 | B6: شَواذّ | C6: noun:peculiarities;idiosyncrasies
A7: 7 | B7: اِسْتَنْقَص | C7: verb:ask for a reduction;find deficient
A8: 8 | B8: أُراق | C8: noun:jaundice
A9: 9 | B9: اِصْطَكّ | C9: verb:tremble;shake
A10: 10 | B10: طِباخَة | C10: noun:cuisine;cooking
A11: 11 | B11: تَقاعُس | C11: noun:negligence
A12: 12 | B12: تَحَسُّر | C12: noun:regret
... A100: 100 | B100: تَوَلَّد | C100: verb:be generated;be produced
A101: x | B101: أَثْخَن | C101: verb:be massacred;be worn out;massacre;wear out
A102: x | B102: جُزْلان | C102: noun:wallet
A103: x | B103: مَرَث | C103: verb:bite;crush;macerate
A104: x | B104: تَذْيِيل | C104: noun:supplementing;appending
A105: x | B105: ذاكَر | C105: verb:negotiate
A106: x | B106: ناصِف | C106: noun:servant;servants
A107: x | B107: فِرْزان | C107: noun:queen;queens
A108: x | B108: أَبْعادِيَّة | C108: noun:country estate
A109: x | B109: بَلُّون | C109: noun:balloon
A110: x | B110: آق | C110: verb:bring bad luck;cause hardship
A111: x | B111: مَهْرَقان | C111: noun:shore;coast;ocean
A112: x | B112: طُفال | C112: noun:potter's clay
... A116: x | B116: اِسْتَنْوَق | C116: verb:make a mistake
B117: اِسْتَجْدَى | C117: verb:be implored;be begged;implore;beg
B118: مُسامِر | C118: noun:conversation partner
B119: أَجْل | C119: noun:for sake of;because of
B120: بابُونَج | C120: noun:chamomile
B121: اِسْتِهْجان | C121: noun:disapproval;condemnation
B122: مُسْتَقِرّ | C122: adj:stable;permanent;settled;at ease
B123: سِلاء | C123: noun:cooking butter
B124: بارَع | C124: verb:strive;work
B125: صَفَق | C125: verb:slam;clap;transfuse
B126: دارّ | C126: adj:copious;showering
B127: بُرُنْجُك | C127: noun:gauze;crepe
B128: مُرْتَكِب | C128: adj:perpetrating|noun:perpetrator
... B200: اِنْداس | C200: verb:be stepped on;be crushed;be run over

Sheet Combined
A1: =Nizar!A1 -> 1 | B1: =Nizar!B1 -> نَصَر | C1: =Nizar!C1 -> verb:assist;render victorious;deliver
A2: =Nizar!A2 -> 2 | B2: =Nizar!B2 -> تَضْمِين | C2: =Nizar!C2 -> noun:inclusion;modulation;implication
A3: =Nizar!A3 -> 3 | B3: =Nizar!B3 -> هَوَّم | C3: =Nizar!C3 -> verb:doze off;fall asleep;exaggerate
A4: =Nizar!A4 -> 4 | B4: =Nizar!B4 -> مُونَة | C4: =Nizar!C4 -> noun:provisions;mortar
A5: =Nizar!A5 -> 5 | B5: =Nizar!B5 -> حِمَى | C5: =Nizar!C5 -> noun:protection
A6: =Nizar!A6 -> 6 | B6: =Nizar!B6 -> غَنَم | C6: =Nizar!C6 -> noun:sheep;goat;goats;sheep;goats
A7: =Nizar!A7 -> 7 | B7: =Nizar!B7 -> مِران | C7: =Nizar!C7 -> noun:practice;experience;skill
A8: =Nizar!A8 -> 8 | B8: =Nizar!B8 -> مُتَطَيِّر | C8: =Nizar!C8 -> adj:pessimist;superstitious
A9: =Nizar!A9 -> 9 | B9: =Nizar!B9 -> تَبَرَّج | C9: =Nizar!C9 -> verb:adorn;embellish
A10: =Nizar!A10 -> 10 | B10: =Nizar!B10 -> أَشْدَق | C10: =Nizar!C10 -> adj:loud-mouthed
A11: =Nizar!A11 -> 11 | B11: =Nizar!B11 -> تَرْنِيخ | C11: =Nizar!C11 -> noun:stagnation
A12: =Nizar!A12 -> 12 | B12: =Nizar!B12 -> مُبَيِّن | C12: =Nizar!C12 -> adj:indicating|noun:indicator
... A100: =Nizar!A100 -> 100 | B100: =Nizar!B100 -> نُشُوئِيّ | C100: =Nizar!C100 -> adj:evolutionist
A101: =Sara!A1+100 -> 101 | B101: =Sara!B1 -> ضُلُوع | C101: =Sara!C1 -> noun:involvement;complicity
A102: =Sara!A2+100 -> 102 | B102: =Sara!B2 -> تَحَفَّى | C102: =Sara!C2 -> verb:be affectionate
A103: =Sara!A3+100 -> 103 | B103: =Sara!B3 -> تَكْتَكَة | C103: =Sara!C3 -> noun:ticking
A104: =Sara!A4+100 -> 104 | B104: =Sara!B4 -> عَذْب | C104: =Sara!C4 -> adj:sweet;pleasant
A105: =Sara!A5+100 -> 105 | B105: =Sara!B5 -> أَنِيمِيّ | C105: =Sara!C5 -> adj:anemic
A106: =Sara!A6+100 -> 106 | B106: =Sara!B6 -> رَهْو | C106: =Sara!C6 -> noun:calm;quiet;tranquillity;crane;cranes
A107: =Sara!A7+100 -> 107 | B107: =Sara!B7 -> مُصاب | C107: =Sara!C7 -> adj:afflicted;injured;wounded|noun:afflicted;injured;wounded
A108: =Sara!A8+100 -> 108 | B108: =Sara!B8 -> حاضِرَة | C108: =Sara!C8 -> noun:capital cities;metropolis
A109: =Sara!A9+100 -> 109 | B109: =Sara!B9 -> وَحْف | C109: =Sara!C9 -> noun:luxuriant;black
A110: =Sara!A10+100 -> 110 | B110: =Sara!B10 -> أَخْصَب | C110: =Sara!C10 -> verb:be fertile|adj_comp:more/most fertile;more/most productive
A111: =Sara!A11+100 -> 111 | B111: =Sara!B11 -> تَفَخَّر | C111: =Sara!C11 -> verb:be proud
A112: =Sara!A12+100 -> 112 | B112: =Sara!B12 -> شَهْر | C112: =Sara!C12 -> noun:month;months
... A200: =Sara!A100+100 -> 200 | B200: =Sara!B100 -> اِنْحَدَر | C200: =Sara!C100 -> verb:descend;decline;come (from)
A201: =Nasser!A1+200 -> 201 | B201: =Nasser!B1 -> جارِحَة | C201: =Nasser!C1 -> noun:extremities;predatory
A202: =Nasser!A2+200 -> 202 | B202: =Nasser!B2 -> سَوِيّ | C202: =Nasser!C2 -> adj:straight;correct;together;jointly;in common
A203: =Nasser!A3+200 -> 203 | B203: =Nasser!B3 -> أُوام | C203: =Nasser!C3 -> noun:thirst
A204: =Nasser!A4+200 -> 204 | B204: =Nasser!B4 -> جِوار | C204: =Nasser!C4 -> noun:near;proximity;next to
A205: =Nasser!A5+200 -> 205 | B205: =Nasser!B5 -> رَتابَة | C205: =Nasser!C5 -> noun:monotony
A206: =Nasser!A6+200 -> 206 | B206: =Nasser!B6 -> قَطْرانِيّ | C206: =Nasser!C6 -> adj:tar-like
A207: =Nasser!A7+200 -> 207 | B207: =Nasser!B7 -> مُشْتَمَل | C207: =Nasser!C7 -> noun:contents
A208: =Nasser!A8+200 -> 208 | B208: =Nasser!B8 -> كَدَم | C208: =Nasser!C8 -> verb:bite;bruise
A209: =Nasser!A9+200 -> 209 | B209: =Nasser!B9 -> فُنْدُقِيّ | C209: =Nasser!C9 -> adj:hotel;hotel-management
A210: =Nasser!A10+200 -> 210 | B210: =Nasser!B10 -> دَرَكِيّ | C210: =Nasser!C10 -> adj:policeman
A211: =Nasser!A11+200 -> 211 | B211: =Nasser!B11 -> مِنَوِيّ | C211: =Nasser!C11 -> adj:seminal;semen
A212: =Nasser!A12+200 -> 212 | B212: =Nasser!B12 -> نَفْسِيّ | C212: =Nasser!C12 -> adj:mental;spiritual;psychological
... A300: =Nasser!A100+200 -> 300 | B300: =Nasser!B100 -> بادَر | C300: =Nasser!C100 -> verb:initiate;surprise
A301: =Salam!A1+300 -> 301 | B301: =Salam!B1 -> مَجَرِّيّ | C301: =Salam!C1 -> adj:galactic
...
